<mujoco model="go2">
  <compiler angle="radian" meshdir="assets" autolimits="true" />

  <option cone="elliptic" impratio="100" />

  <default>
    <default class="go2">
      <geom friction="0.4" margin="0.001" condim="1"/>
      <joint axis="0 1 0" damping="0.1" armature="0.01" frictionloss="0.2"/>
      <motor ctrlrange="-23.7 23.7"/>
      <default class="abduction">
        <joint axis="1 0 0" range="-1.0472 1.0472"/>
      </default>
      <default class="hip">
        <default class="front_hip">
          <joint range="-1.5708 3.4907"/>
        </default>
        <default class="back_hip">
          <joint range="-0.5236 4.5379"/>
        </default>
      </default>
      <default class="knee">
        <joint range="-2.7227 -0.83776"/>
        <motor ctrlrange="-45.43 45.43"/>
      </default>
      <default class="visual">
        <geom type="mesh" contype="0" conaffinity="0" group="2"/>
      </default>
      <default class="collision">
        <geom group="3"/>
        <default class="foot">
          <geom size="0.022" pos="-0.002 0 -0.213" priority="1" condim="6"
            friction="0.4 0.02 0.01"/>
        </default>
      </default>
    </default>
  </default>

  <asset>
    <material name="metal" rgba=".9 .95 .95 1" />
    <material name="black" rgba="0 0 0 1" />
    <material name="white" rgba="1 1 1 1" />
    <material name="gray" rgba="0.671705 0.692426 0.774270 1" />

    <mesh file="base_0.obj" />
    <mesh file="base_1.obj" />
    <mesh file="base_2.obj" />
    <mesh file="base_3.obj" />
    <mesh file="base_4.obj" />
    <mesh file="hip_0.obj" />
    <mesh file="hip_1.obj" />
    <mesh file="thigh_0.obj" />
    <mesh file="thigh_1.obj" />
    <mesh file="thigh_mirror_0.obj" />
    <mesh file="thigh_mirror_1.obj" />
    <mesh file="calf_0.obj" />
    <mesh file="calf_1.obj" />
    <mesh file="calf_mirror_0.obj" />
    <mesh file="calf_mirror_1.obj" />
    <mesh file="foot.obj" />

    <mesh name="arm_base_link" file="../../meshes/piper/base_link.stl" />
    <mesh name="arm_link1" file="../../meshes/piper/link1.stl" />
    <mesh name="arm_link2" file="../../meshes/piper/link2.stl" />
    <mesh name="arm_link3" file="../../meshes/piper/link3.stl" />
    <mesh name="arm_link4" file="../../meshes/piper/link4.stl" />
    <mesh name="arm_link5" file="../../meshes/piper/link5.stl" />
    <mesh name="arm_link6" file="../../meshes/piper/link6.stl" />
    <mesh name="gripper_base" file="../../meshes/piper/gripper_base.stl" />
    <mesh name="gripper_link1" file="../../meshes/piper/gripper_link1.stl" />
    <mesh name="gripper_link2" file="../../meshes/piper/gripper_link2.stl" />

    <mesh name="arm_base_link_col" file="../../meshes/piper/base_link.stl" />
    <mesh name="arm_link1_col" file="../../meshes/piper/link1.stl" />
    <mesh name="arm_link2_col" file="../../meshes/piper/link2.stl" />
    <mesh name="arm_link3_col" file="../../meshes/piper/link3.stl" />
    <mesh name="arm_link4_col" file="../../meshes/piper/link4.stl" />
    <mesh name="arm_link5_col" file="../../meshes/piper/link5.stl" />
    <mesh name="arm_link6_col" file="../../meshes/piper/link6.stl" />
    <mesh name="gripper_base_col" file="../../meshes/piper/gripper_base.stl" />
    <mesh name="gripper_link1_col" file="../../meshes/piper/gripper_link1.stl" />
    <mesh name="gripper_link2_col" file="../../meshes/piper/gripper_link2.stl" />
    
  </asset>

  <worldbody>
    <body name="base_link" pos="0 0 0.445" childclass="go2">
      <inertial pos="0.021112 0 -0.005366" quat="-0.000543471 0.713435 -0.00173769 0.700719"
        mass="6.921"
        diaginertia="0.107027 0.0980771 0.0244531" />
      <freejoint />
      <geom mesh="base_0" material="black" class="visual" />
      <geom mesh="base_1" material="black" class="visual" />
      <geom mesh="base_2" material="black" class="visual" />
      <geom mesh="base_3" material="white" class="visual" />
      <geom mesh="base_4" material="gray" class="visual" />
      <geom size="0.1881 0.04675 0.057" type="box" class="collision" />
      <geom size="0.05 0.045" pos="0.285 0 0.01" type="cylinder" class="collision" />
      <geom size="0.047" pos="0.293 0 -0.06" class="collision" />
      <site name="imu" pos="-0.02557 0 0.04232" />
      <body name="FL_hip" pos="0.1934 0.0465 0">
        <inertial pos="-0.0054 0.00194 -0.000105" quat="0.497014 0.499245 0.505462 0.498237"
          mass="0.678"
          diaginertia="0.00088403 0.000596003 0.000479967" />
        <joint name="FL_hip_joint" class="abduction" />
        <geom mesh="hip_0" material="metal" class="visual" />
        <geom mesh="hip_1" material="gray" class="visual" />
        <geom size="0.046 0.02" pos="0 0.08 0" quat="1 1 0 0" type="cylinder" class="collision" />
        <body name="FL_thigh" pos="0 0.0955 0">
          <inertial pos="-0.00374 -0.0223 -0.0327" quat="0.829533 0.0847635 -0.0200632 0.551623"
            mass="1.152"
            diaginertia="0.00594973 0.00584149 0.000878787" />
          <joint name="FL_thigh_joint" class="front_hip" />
          <geom mesh="thigh_0" material="metal" class="visual" />
          <geom mesh="thigh_1" material="gray" class="visual" />
          <geom size="0.1065 0.01225 0.017" pos="0 0 -0.1065" quat="0.707107 0 0.707107 0"
            type="box" class="collision" />
          <body name="FL_calf" pos="0 0 -0.213">
            <inertial pos="0.00629595 -0.000622121 -0.141417"
              quat="0.710672 0.00154099 -0.00450087 0.703508"
              mass="0.241352" diaginertia="0.0014901 0.00146356 5.31397e-05" />
            <joint name="FL_calf_joint" class="knee" />
            <geom mesh="calf_0" material="gray" class="visual" />
            <geom mesh="calf_1" material="black" class="visual" />
            <geom size="0.012 0.06" pos="0.008 0 -0.06" quat="0.994493 0 -0.104807 0"
              type="cylinder" class="collision" />
            <geom size="0.011 0.0325" pos="0.02 0 -0.148" quat="0.999688 0 0.0249974 0"
              type="cylinder" class="collision" />
            <geom pos="0 0 -0.213" mesh="foot" class="visual" material="black" />
            <geom name="FL" class="foot" />
            <body name="FL_foot" pos="0 0 -0.213" />
          </body>
        </body>
      </body>
      <body name="FR_hip" pos="0.1934 -0.0465 0">
        <inertial pos="-0.0054 -0.00194 -0.000105" quat="0.498237 0.505462 0.499245 0.497014"
          mass="0.678"
          diaginertia="0.00088403 0.000596003 0.000479967" />
        <joint name="FR_hip_joint" class="abduction" />
        <geom mesh="hip_0" material="metal" class="visual" quat="4.63268e-05 1 0 0" />
        <geom mesh="hip_1" material="gray" class="visual" quat="4.63268e-05 1 0 0" />
        <geom size="0.046 0.02" pos="0 -0.08 0" quat="0.707107 0.707107 0 0" type="cylinder"
          class="collision" />
        <body name="FR_thigh" pos="0 -0.0955 0">
          <inertial pos="-0.00374 0.0223 -0.0327" quat="0.551623 -0.0200632 0.0847635 0.829533"
            mass="1.152"
            diaginertia="0.00594973 0.00584149 0.000878787" />
          <joint name="FR_thigh_joint" class="front_hip" />
          <geom mesh="thigh_mirror_0" material="metal" class="visual" />
          <geom mesh="thigh_mirror_1" material="gray" class="visual" />
          <geom size="0.1065 0.01225 0.017" pos="0 0 -0.1065" quat="0.707107 0 0.707107 0"
            type="box" class="collision" />
          <body name="FR_calf" pos="0 0 -0.213">
            <inertial pos="0.00629595 0.000622121 -0.141417"
              quat="0.703508 -0.00450087 0.00154099 0.710672"
              mass="0.241352" diaginertia="0.0014901 0.00146356 5.31397e-05" />
            <joint name="FR_calf_joint" class="knee" />
            <geom mesh="calf_mirror_0" material="gray" class="visual" />
            <geom mesh="calf_mirror_1" material="black" class="visual" />
            <geom size="0.013 0.06" pos="0.01 0 -0.06" quat="0.995004 0 -0.0998334 0"
              type="cylinder" class="collision" />
            <geom size="0.011 0.0325" pos="0.02 0 -0.148" quat="0.999688 0 0.0249974 0"
              type="cylinder" class="collision" />
            <geom pos="0 0 -0.213" mesh="foot" class="visual" material="black" />
            <geom name="FR" class="foot" />
            <body name="FR_foot" pos="0 0 -0.213" />
          </body>
        </body>
      </body>
      <body name="RL_hip" pos="-0.1934 0.0465 0">
        <inertial pos="0.0054 0.00194 -0.000105" quat="0.505462 0.498237 0.497014 0.499245"
          mass="0.678"
          diaginertia="0.00088403 0.000596003 0.000479967" />
        <joint name="RL_hip_joint" class="abduction" />
        <geom mesh="hip_0" material="metal" class="visual" quat="4.63268e-05 0 1 0" />
        <geom mesh="hip_1" material="gray" class="visual" quat="4.63268e-05 0 1 0" />
        <geom size="0.046 0.02" pos="0 0.08 0" quat="0.707107 0.707107 0 0" type="cylinder"
          class="collision" />
        <body name="RL_thigh" pos="0 0.0955 0">
          <inertial pos="-0.00374 -0.0223 -0.0327" quat="0.829533 0.0847635 -0.0200632 0.551623"
            mass="1.152"
            diaginertia="0.00594973 0.00584149 0.000878787" />
          <joint name="RL_thigh_joint" class="back_hip" />
          <geom mesh="thigh_0" material="metal" class="visual" />
          <geom mesh="thigh_1" material="gray" class="visual" />
          <geom size="0.1065 0.01225 0.017" pos="0 0 -0.1065" quat="0.707107 0 0.707107 0"
            type="box" class="collision" />
          <body name="RL_calf" pos="0 0 -0.213">
            <inertial pos="0.00629595 -0.000622121 -0.141417"
              quat="0.710672 0.00154099 -0.00450087 0.703508"
              mass="0.241352" diaginertia="0.0014901 0.00146356 5.31397e-05" />
            <joint name="RL_calf_joint" class="knee" />
            <geom mesh="calf_0" material="gray" class="visual" />
            <geom mesh="calf_1" material="black" class="visual" />
            <geom size="0.013 0.06" pos="0.01 0 -0.06" quat="0.995004 0 -0.0998334 0"
              type="cylinder" class="collision" />
            <geom size="0.011 0.0325" pos="0.02 0 -0.148" quat="0.999688 0 0.0249974 0"
              type="cylinder" class="collision" />
            <geom pos="0 0 -0.213" mesh="foot" class="visual" material="black" />
            <geom name="RL" class="foot" />
            <body name="RL_foot" pos="0 0 -0.213" />
          </body>
        </body>
      </body>
      <body name="RR_hip" pos="-0.1934 -0.0465 0">
        <inertial pos="0.0054 -0.00194 -0.000105" quat="0.499245 0.497014 0.498237 0.505462"
          mass="0.678"
          diaginertia="0.00088403 0.000596003 0.000479967" />
        <joint name="RR_hip_joint" class="abduction" />
        <geom mesh="hip_0" material="metal" class="visual"
          quat="2.14617e-09 4.63268e-05 4.63268e-05 -1" />
        <geom mesh="hip_1" material="gray" class="visual"
          quat="2.14617e-09 4.63268e-05 4.63268e-05 -1" />
        <geom size="0.046 0.02" pos="0 -0.08 0" quat="0.707107 0.707107 0 0" type="cylinder"
          class="collision" />
        <body name="RR_thigh" pos="0 -0.0955 0">
          <inertial pos="-0.00374 0.0223 -0.0327" quat="0.551623 -0.0200632 0.0847635 0.829533"
            mass="1.152"
            diaginertia="0.00594973 0.00584149 0.000878787" />
          <joint name="RR_thigh_joint" class="back_hip" />
          <geom mesh="thigh_mirror_0" material="metal" class="visual" />
          <geom mesh="thigh_mirror_1" material="gray" class="visual" />
          <geom size="0.1065 0.01225 0.017" pos="0 0 -0.1065" quat="0.707107 0 0.707107 0"
            type="box" class="collision" />
          <body name="RR_calf" pos="0 0 -0.213">
            <inertial pos="0.00629595 0.000622121 -0.141417"
              quat="0.703508 -0.00450087 0.00154099 0.710672"
              mass="0.241352" diaginertia="0.0014901 0.00146356 5.31397e-05" />
            <joint name="RR_calf_joint" class="knee" />
            <geom mesh="calf_mirror_0" material="gray" class="visual" />
            <geom mesh="calf_mirror_1" material="black" class="visual" />
            <geom size="0.013 0.06" pos="0.01 0 -0.06" quat="0.995004 0 -0.0998334 0"
              type="cylinder" class="collision" />
            <geom size="0.011 0.0325" pos="0.02 0 -0.148" quat="0.999688 0 0.0249974 0"
              type="cylinder" class="collision" />
            <geom pos="0 0 -0.213" mesh="foot" class="visual" material="black" />
            <geom name="RR" class="foot" />
            <body name="RR_foot" pos="0 0 -0.213" />
          </body>
        </body>
      </body>
        <body name="arm_base_link" pos="0.15 0 0.085">
          <inertial pos="-0.00473641164191482 0.0000256829134630247 0.041451518036016"
            mass="1.02" diaginertia="0.00267433 0.00282612 0.00089624" />
          <geom mesh="arm_base_link" material="metal" class="visual" />
          <geom mesh="arm_base_link_col" type="mesh" class="collision" />
          <body name="arm_link1" pos="0 0 0.123">
            <inertial pos="0.00032 -0.00041 -0.00348" mass="0.71"
              diaginertia="0.00050027 0.00040879 0.00045802" />
            <joint name="arm_joint1" axis="0 0 1" range="-2.6179938 2.6179938" />
            <geom mesh="arm_link1" material="metal" class="visual" />
            <geom mesh="arm_link1_col" type="mesh" class="collision" />
            <body name="arm_link2" pos="0 0 0" quat="0.04797096 -0.04797092 -0.70547769 -0.70547771">
              <inertial pos="0.21852 -0.00861 0.00126" mass="1.16"
                diaginertia="0.00111915 0.06763251 0.067559" />
              <joint name="arm_joint2" axis="0 0 1" range="0 3.1415926" />
              <geom mesh="arm_link2" material="metal" class="visual" />
              <geom mesh="arm_link2_col" type="mesh" class="collision" />
              <body name="arm_link3" pos="0.28503 0 0" quat="0.62401599 0 0 -0.78141157">
                <inertial pos="-0.01999 -0.14808 -0.00053" mass="0.5"
                  diaginertia="0.01347608 0.00046377 0.01363321" />
                <joint name="arm_joint3" axis="0 0 1" range="-2.9670597 0" />
                <geom mesh="arm_link3" material="metal" class="visual" />
                <geom mesh="arm_link3_col" type="mesh" class="collision" />
                <body name="arm_link4" pos="-0.02198 -0.25075 0" quat="0.70710679 0.70710677 0 0">
                  <inertial pos="0.00013 -0.00076 -0.00394" mass="0.38"
                    diaginertia="0.00017844 0.00018914 0.00014613" />
                  <joint name="arm_joint4" axis="0 0 1" range="-1.7453292 1.7453292" />
                  <geom mesh="arm_link4" material="metal" class="visual" />
                  <geom mesh="arm_link4_col" type="mesh" class="collision" />
                  <body name="arm_link5" pos="0 0 0" quat="0.70710679 -0.70710677 0 0">
                    <inertial pos="0.00018 -0.06104 -0.00227" mass="0.383"
                      diaginertia="0.00172318 0.00017936 0.00171172" />
                    <joint name="arm_joint5" axis="0 0 1" range="-1.2217304 1.2217304" />
                    <geom mesh="arm_link5" material="metal" class="visual" />
                    <geom mesh="arm_link5_col" type="mesh" class="collision" />
                    <body name="arm_link6" pos="0.000088259 -0.091 0" quat="0.70710679 0.70710677 0 0">
                      <inertial pos="-0.00003 0.00006 -0.002" mass="0.007"
                        diaginertia="0.00152112 0.00138626 0.00031152" />
                      <joint name="arm_joint6" axis="0 0 1" range="-2.0943951 2.0943951" />
                      <geom mesh="arm_link6" material="metal" class="visual" />
                      <geom mesh="arm_link6_col" type="mesh" class="collision" />
                      <body name="gripper_base" pos="0 0 0">
                        <inertial pos="-0.000183807162235591 0.0000805033155577911 0.0321436689908876"
                          mass="0.45" diaginertia="0.00092934 0.00071447 0.00039442" />
                        <geom mesh="gripper_base" material="black" class="visual" />
                        <geom mesh="gripper_base_col" type="mesh" class="collision" />
                        <body name="gripper_link1" pos="0 0 0.1358" quat="0.70710679 0.70710677 0 0">
                          <inertial pos="0.00065123185041968 -0.0491929869131989 0.00972258769184025"
                            mass="0.025" diaginertia="0.00007371 0.00000781 0.0000747" />
                          <!-- <joint name="gripper_joint1" type="slide" axis="0 0 1" range="0 0.05" /> -->
                          <geom mesh="gripper_link1" material="black" class="visual" />
                          <geom mesh="gripper_link1_col" type="mesh" class="collision" />
                        </body>
                        <body name="gripper_link2" pos="0 0 0.1358" quat="0.00000002 0.00000002 -0.70710677 -0.70710679">
                          <inertial pos="0.00065123185041968 -0.0491929869131989 0.00972258769184025"
                            mass="0.025" diaginertia="0.00007371 0.00000781 0.0000747" />
                          <!-- <joint name="gripper_joint2" type="slide" axis="0 0 -1" range="-0.05 0" /> -->
                          <geom mesh="gripper_link2" material="black" class="visual" />
                          <geom mesh="gripper_link2_col" type="mesh" class="collision" />
                        </body>
                      </body>
                    </body>
                  </body>
                </body>
              </body>
            </body>
          </body>
        </body>
    </body>
  </worldbody>

  <actuator>
    <motor class="abduction" name="FR_hip" joint="FR_hip_joint" />
    <motor class="hip" name="FR_thigh" joint="FR_thigh_joint" />
    <motor class="knee" name="FR_calf" joint="FR_calf_joint" />
    <motor class="abduction" name="FL_hip" joint="FL_hip_joint" />
    <motor class="hip" name="FL_thigh" joint="FL_thigh_joint" />
    <motor class="knee" name="FL_calf" joint="FL_calf_joint" />
    <motor class="abduction" name="RR_hip" joint="RR_hip_joint" />
    <motor class="hip" name="RR_thigh" joint="RR_thigh_joint" />
    <motor class="knee" name="RR_calf" joint="RR_calf_joint" />
    <motor class="abduction" name="RL_hip" joint="RL_hip_joint" />
    <motor class="hip" name="RL_thigh" joint="RL_thigh_joint" />
    <motor class="knee" name="RL_calf" joint="RL_calf_joint" />
    <motor name="arm_joint1" joint="arm_joint1" />
    <motor name="arm_joint2" joint="arm_joint2" />
    <motor name="arm_joint3" joint="arm_joint3" />
    <motor name="arm_joint4" joint="arm_joint4" />
    <motor name="arm_joint5" joint="arm_joint5" />
    <motor name="arm_joint6" joint="arm_joint6" />
    <!-- <motor name="gripper_joint1" joint="gripper_joint1" />
    <motor name="gripper_joint2" joint="gripper_joint2" /> -->
  </actuator>

  <sensor>
    <jointpos name="FR_hip_pos" joint="FR_hip_joint" />
    <jointpos name="FR_thigh_pos" joint="FR_thigh_joint" />
    <jointpos name="FR_calf_pos" joint="FR_calf_joint" />
    <jointpos name="FL_hip_pos" joint="FL_hip_joint" />
    <jointpos name="FL_thigh_pos" joint="FL_thigh_joint" />
    <jointpos name="FL_calf_pos" joint="FL_calf_joint" />
    <jointpos name="RR_hip_pos" joint="RR_hip_joint" />
    <jointpos name="RR_thigh_pos" joint="RR_thigh_joint" />
    <jointpos name="RR_calf_pos" joint="RR_calf_joint" />
    <jointpos name="RL_hip_pos" joint="RL_hip_joint" />
    <jointpos name="RL_thigh_pos" joint="RL_thigh_joint" />
    <jointpos name="RL_calf_pos" joint="RL_calf_joint" />
    <jointpos name="arm_joint1_pos" joint="arm_joint1" />
    <jointpos name="arm_joint2_pos" joint="arm_joint2" />
    <jointpos name="arm_joint3_pos" joint="arm_joint3" />
    <jointpos name="arm_joint4_pos" joint="arm_joint4" />
    <jointpos name="arm_joint5_pos" joint="arm_joint5" />
    <jointpos name="arm_joint6_pos" joint="arm_joint6" />
    <!-- <jointpos name="gripper_joint1_pos" joint="gripper_joint1" />
    <jointpos name="gripper_joint2_pos" joint="gripper_joint2" /> -->

    <jointvel name="FR_hip_vel" joint="FR_hip_joint" />
    <jointvel name="FR_thigh_vel" joint="FR_thigh_joint" />
    <jointvel name="FR_calf_vel" joint="FR_calf_joint" />
    <jointvel name="FL_hip_vel" joint="FL_hip_joint" />
    <jointvel name="FL_thigh_vel" joint="FL_thigh_joint" />
    <jointvel name="FL_calf_vel" joint="FL_calf_joint" />
    <jointvel name="RR_hip_vel" joint="RR_hip_joint" />
    <jointvel name="RR_thigh_vel" joint="RR_thigh_joint" />
    <jointvel name="RR_calf_vel" joint="RR_calf_joint" />
    <jointvel name="RL_hip_vel" joint="RL_hip_joint" />
    <jointvel name="RL_thigh_vel" joint="RL_thigh_joint" />
    <jointvel name="RL_calf_vel" joint="RL_calf_joint" />
    <jointvel name="arm_joint1_vel" joint="arm_joint1" />
    <jointvel name="arm_joint2_vel" joint="arm_joint2" />
    <jointvel name="arm_joint3_vel" joint="arm_joint3" />
    <jointvel name="arm_joint4_vel" joint="arm_joint4" />
    <jointvel name="arm_joint5_vel" joint="arm_joint5" />
    <jointvel name="arm_joint6_vel" joint="arm_joint6" />

    <jointactuatorfrc name="FR_hip_torque" joint="FR_hip_joint" noise="0.01" />
    <jointactuatorfrc name="FR_thigh_torque" joint="FR_thigh_joint" noise="0.01" />
    <jointactuatorfrc name="FR_calf_torque" joint="FR_calf_joint" noise="0.01" />
    <jointactuatorfrc name="FL_hip_torque" joint="FL_hip_joint" noise="0.01" />
    <jointactuatorfrc name="FL_thigh_torque" joint="FL_thigh_joint" noise="0.01" />
    <jointactuatorfrc name="FL_calf_torque" joint="FL_calf_joint" noise="0.01" />
    <jointactuatorfrc name="RR_hip_torque" joint="RR_hip_joint" noise="0.01" />
    <jointactuatorfrc name="RR_thigh_torque" joint="RR_thigh_joint" noise="0.01" />
    <jointactuatorfrc name="RR_calf_torque" joint="RR_calf_joint" noise="0.01" />
    <jointactuatorfrc name="RL_hip_torque" joint="RL_hip_joint" noise="0.01" />
    <jointactuatorfrc name="RL_thigh_torque" joint="RL_thigh_joint" noise="0.01" />
    <jointactuatorfrc name="RL_calf_torque" joint="RL_calf_joint" noise="0.01" />
    <jointactuatorfrc name="arm_joint1_torque" joint="arm_joint1" noise="0.01" />
    <jointactuatorfrc name="arm_joint2_torque" joint="arm_joint2" noise="0.01" />
    <jointactuatorfrc name="arm_joint3_torque" joint="arm_joint3" noise="0.01" />
    <jointactuatorfrc name="arm_joint4_torque" joint="arm_joint4" noise="0.01" />
    <jointactuatorfrc name="arm_joint5_torque" joint="arm_joint5" noise="0.01" />
    <jointactuatorfrc name="arm_joint6_torque" joint="arm_joint6" noise="0.01" />
    <!-- <jointactuatorfrc name="gripper_joint1_force" joint="gripper_joint1" noise="0.01" />
    <jointactuatorfrc name="gripper_joint2_force" joint="gripper_joint2" noise="0.01" /> -->

    <framequat name="imu_quat" objtype="site" objname="imu" />
    <gyro name="imu_gyro" site="imu" />
    <accelerometer name="imu_acc" site="imu" />
    
    <framepos name="frame_pos" objtype="site" objname="imu" />
    <framelinvel name="frame_vel" objtype="site" objname="imu" />
  </sensor>

  <keyframe>
    <!-- <key name="home" qpos="0 0 0.27 1 0 0 0 0 0.9 -1.8 0 0.9 -1.8 0 0.9 -1.8 0 0.9 -1.8 0 0 0 0 0 0 0 0" -->
      <key name="home" qpos="0 0 0.27 1 0 0 0 0 0.9 -1.8 0 0.9 -1.8 0 0.9 -1.8 0 0.9 -1.8 0 0 0 0 0 0 "
      ctrl="0 0.9 -1.8 0 0.9 -1.8 0 0.9 -1.8 0 0.9 -1.8" />
  </keyframe>
  <!-- setup scene -->
  <statistic center="1.0 1.0 1.0" extent="0.8"/>
  <visual>
    <headlight diffuse="0.6 0.6 0.6" ambient="0.1 0.1 0.1" specular="0.9 0.9 0.9"/>
    <rgba haze="0.15 0.25 0.35 1"/>
    <global azimuth="-140" elevation="-20"/>
  </visual>
  <asset>
    <texture type="skybox" builtin="flat" rgb1="0 0 0" rgb2="0 0 0" width="512" height="3072"/>
    <texture type="2d" name="groundplane" builtin="checker" mark="edge" rgb1="0.2 0.3 0.4" rgb2="0.1 0.2 0.3" markrgb="0.8 0.8 0.8" width="300" height="300"/>
    <material name="groundplane" texture="groundplane" texuniform="true" texrepeat="5 5" reflectance="0.2"/>
  </asset>
  <worldbody>
    <light pos="1 0 3.5" dir="0 0 -1" directional="true"/>
    <geom name="floor" size="0 0 0.05" type="plane" material="groundplane"/>
  </worldbody>
</mujoco>