<?xml version='1.0' encoding='utf-8'?>
<robot name="go_b">
  <link name="base">
    <inertial>
      <origin xyz="0.021112 0 -0.005366" rpy="0 0 0" />
      <mass value="6.921" />
      <inertia ixx="0.02448" ixy="0.00012166" ixz="0.0014849" iyy="0.098077" iyz="-3.12E-05" izz="0.107" />
    </inertial>
    <visual>
      <origin xyz="0 0 0" rpy="0 0 0" />
      <geometry>
        <mesh filename="package://go_b/dae/base.dae" />
      </geometry>
      <material name="深色橡胶_001-effect"><color rgba="0.6717055 0.6924257 0.7742702 1" /></material><material name="白色logo_001-effect"><color rgba="1 1 1 1" /></material><material name="黑色贴纸_007-effect"><color rgba="0.009018 0.009018 0.009018 1" /></material><material name="黑色金属_007-effect"><color rgba="0.01341 0.01341 0.01341 1" /></material><material name="黑色塑料_003-effect"><color rgba="0.023455 0.023455 0.023455 1" /></material></visual>
    <collision>
      <origin rpy="0 0 0" xyz="0 0 0" />
      <geometry>
        <box size="0.3762 0.0935 0.114" />
      </geometry>
    </collision>
  </link>
  <link name="Head_upper">
    <inertial>
      <origin xyz="0 0 0" rpy="0 0 0" />
      <mass value="0.001" />
      <inertia ixx="9.6e-06" ixy="0" ixz="0" iyy="9.6e-06" iyz="0" izz="9.6e-06" />
    </inertial>
    <collision>
      <origin xyz="0 0 0" rpy="0 0 0" />
      <geometry>
        <cylinder radius="0.05" length="0.09" />
      </geometry>
    </collision>
  </link>
  <joint name="Head_upper_joint" type="fixed" dont_collapse="true">
    <origin xyz="0.285 0 0.01" rpy="0 0 0" />
    <parent link="base" />
    <child link="Head_upper" />
    <axis xyz="0 0 0" />
  </joint>
  <link name="Head_lower">
    <inertial>
      <origin xyz="0 0 0" rpy="0 0 0" />
      <mass value="0.001" />
      <inertia ixx="9.6e-06" ixy="0" ixz="0" iyy="9.6e-06" iyz="0" izz="9.6e-06" />
    </inertial>
    <collision>
      <origin xyz="0 0 0" rpy="0 0 0" />
      <geometry>
        <sphere radius="0.047" />
      </geometry>
    </collision>
  </link>
  <joint name="Head_lower_joint" type="fixed" dont_collapse="true">
    <origin xyz="0.008 0 -0.07" rpy="0 0 0" />
    <parent link="Head_upper" />
    <child link="Head_lower" />
    <axis xyz="0 0 0" />
  </joint>
  <link name="FL_hip">
    <inertial>
      <origin xyz="-0.0054 0.00194 -0.000105" rpy="0 0 0" />
      <mass value="0.678" />
      <inertia ixx="0.00048" ixy="-3.01E-06" ixz="1.11E-06" iyy="0.000884" iyz="-1.42E-06" izz="0.000596" />
    </inertial>
    <visual>
      <origin xyz="0 0 0" rpy="0 0 0" />
      <geometry>
        <mesh filename="package://go_b/dae/hip.dae" />
      </geometry>
      <material name="深色橡胶_001-effect"><color rgba="0.6717055 0.6924257 0.7742702 1" /></material><material name="Material-effect"><color rgba="0.9 0.95 0.95 1" /></material></visual>
    <collision>
      <origin rpy="1.5707963267948966 0 0" xyz="0 0.08 0" />
      <geometry>
        <cylinder length="0.04" radius="0.046" />
      </geometry>
    </collision>
  </link>
  <joint name="FL_hip_joint" type="revolute">
    <origin xyz="0.1934 0.0465 0" rpy="0 0 0" />
    <parent link="base" />
    <child link="FL_hip" />
    <axis xyz="1 0 0" />
    <limit lower="-1.0472" upper="1.0472" effort="23.7" velocity="30.1" />
  </joint>
  <link name="FL_hip_rotor">
    <inertial>
      <origin rpy="0 0 0" xyz="0.0 0.0 0.0" />
      <mass value="0.089" />
      <inertia ixx="0.000111842" ixy="0.0" ixz="0.0" iyy="0.000059647" iyz="0.0" izz="0.000059647" />
    </inertial>
  </link>
  <joint name="FL_hip_rotor_joint" type="fixed">
    <origin rpy="0 0 0" xyz="0.11215 0.04675 0" />
    <parent link="base" />
    <child link="FL_hip_rotor" />
  </joint>
  <link name="FL_thigh">
    <inertial>
      <origin xyz="-0.00374 -0.0223 -0.0327" rpy="0 0 0" />
      <mass value="1.152" />
      <inertia ixx="0.00584" ixy="8.72E-05" ixz="-0.000289" iyy="0.0058" iyz="0.000808" izz="0.00103" />
    </inertial>
    <visual>
      <origin xyz="0 0 0" rpy="0 0 0" />
      <geometry>
        <mesh filename="package://go_b/dae/thigh.dae" />
      </geometry>
      <material name="深色橡胶_003-effect"><color rgba="0.6717055 0.6924257 0.7742702 1" /></material><material name="Material_009-effect"><color rgba="0.9 0.95 0.95 1" /></material></visual>
    <collision>
      <origin rpy="0 1.5707963267948966 0" xyz="0 0 -0.1065" />
      <geometry>
        <box size="0.213 0.0245 0.034" />
      </geometry>
    </collision>
  </link>
  <joint name="FL_thigh_joint" type="revolute">
    <origin xyz="0 0.0955 0" rpy="0 0 0" />
    <parent link="FL_hip" />
    <child link="FL_thigh" />
    <axis xyz="0 1 0" />
    <limit lower="-1.5708" upper="3.4907" effort="23.7" velocity="30.1" />
  </joint>
  <link name="FL_thigh_rotor">
    <inertial>
      <origin rpy="0 0 0" xyz="0.0 0.0 0.0" />
      <mass value="0.089" />
      <inertia ixx="0.000059647" ixy="0.0" ixz="0.0" iyy="0.000111842" iyz="0.0" izz="0.000059647" />
    </inertial>
  </link>
  <joint name="FL_thigh_rotor_joint" type="fixed">
    <origin rpy="0 0 0" xyz="0 -0.00015 0" />
    <parent link="FL_hip" />
    <child link="FL_thigh_rotor" />
  </joint>
  <link name="FL_calf">
    <inertial>
      <origin xyz="0.00548 -0.000975 -0.115" rpy="0 0 0" />
      <mass value="0.154" />
      <inertia ixx="0.00108" ixy="3.4E-07" ixz="1.72E-05" iyy="0.0011" iyz="8.28E-06" izz="3.29E-05" />
    </inertial>
    <visual>
      <origin xyz="0 0 0" rpy="0 0 0" />
      <geometry>
        <mesh filename="package://go_b/dae/calf.dae" />
      </geometry>
      <material name="黑色足端_005-effect"><color rgba="0 0 0 1" /></material><material name="深色橡胶_005-effect"><color rgba="0.6717055 0.6924257 0.7742702 1" /></material></visual>
    <collision>
      <origin rpy="0 -0.21 0" xyz="0.008 0 -0.06" />
      <geometry>
        <cylinder length="0.12" radius="0.012" />
      </geometry>
    </collision>
  </link>
  <joint name="FL_calf_joint" type="revolute">
    <origin xyz="0 0 -0.213" rpy="0 0 0" />
    <parent link="FL_thigh" />
    <child link="FL_calf" />
    <axis xyz="0 1 0" />
    <limit lower="-2.7227" upper="-0.83776" effort="45.43" velocity="15.70" />
  </joint>
  <link name="FL_calflower">
    <collision>
      <origin rpy="0 0 0" xyz="0 0 0" />
      <geometry>
        <cylinder length="0.065" radius="0.011" />
      </geometry>
    </collision>
  </link>
  <joint name="FL_calflower_joint" type="fixed">
    <origin xyz="0.020 0 -0.148" rpy="0 0.05 0" />
    <parent link="FL_calf" />
    <child link="FL_calflower" />
    <axis xyz="0 0 0" />
  </joint>
  <link name="FL_calflower1">
    <collision>
      <origin rpy="0 0 0" xyz="0 0 0" />
      <geometry>
        <cylinder length="0.03" radius="0.0155" />
      </geometry>
    </collision>
  </link>
  <joint name="FL_calflower1_joint" type="fixed">
    <origin xyz="-0.01 0 -0.04" rpy="0 0.48 0" />
    <parent link="FL_calflower" />
    <child link="FL_calflower1" />
    <axis xyz="0 0 0" />
  </joint>
  <link name="FL_calf_rotor">
    <inertial>
      <origin rpy="0 0 0" xyz="0.0 0.0 0.0" />
      <mass value="0.089" />
      <inertia ixx="0.000059647" ixy="0.0" ixz="0.0" iyy="0.000111842" iyz="0.0" izz="0.000059647" />
    </inertial>
  </link>
  <joint name="FL_calf_rotor_joint" type="fixed">
    <origin rpy="0 0 0" xyz="0 -0.03235 0" />
    <parent link="FL_thigh" />
    <child link="FL_calf_rotor" />
  </joint>
  <link name="FL_foot">
    <inertial>
      <origin xyz="0 0 0" rpy="0 0 0" />
      <mass value="0.04" />
      <inertia ixx="9.6e-06" ixy="0" ixz="0" iyy="9.6e-06" iyz="0" izz="9.6e-06" />
    </inertial>
    <visual>
      <origin xyz="0 0 0" rpy="0 0 0" />
      <geometry>
        <mesh filename="package://go_b/dae/foot.dae" />
      </geometry>
      <material name="黑色足端_007-effect"><color rgba="0 0 0 1" /></material></visual>
    <collision>
      <origin rpy="0 0 0" xyz="-0.002 0 0" />
      <geometry>
        <sphere radius="0.022" />
      </geometry>
    </collision>
  </link>
  <joint name="FL_foot_joint" type="fixed" dont_collapse="true">
    <origin xyz="0 0 -0.213" rpy="0 0 0" />
    <parent link="FL_calf" />
    <child link="FL_foot" />
    <axis xyz="0 0 0" />
  </joint>
  <link name="FR_hip">
    <inertial>
      <origin xyz="-0.0054 -0.00194 -0.000105" rpy="0 0 0" />
      <mass value="0.678" />
      <inertia ixx="0.00048" ixy="3.01E-06" ixz="1.11E-06" iyy="0.000884" iyz="1.42E-06" izz="0.000596" />
    </inertial>
    <visual>
      <origin xyz="0 0 0" rpy="3.1415 0 0" />
      <geometry>
        <mesh filename="package://go_b/dae/hip.dae" />
      </geometry>
      <material name="深色橡胶_001-effect"><color rgba="0.6717055 0.6924257 0.7742702 1" /></material><material name="Material-effect"><color rgba="0.9 0.95 0.95 1" /></material></visual>
    <collision>
      <origin rpy="1.5707963267948966 0 0" xyz="0 -0.08 0" />
      <geometry>
        <cylinder length="0.04" radius="0.046" />
      </geometry>
    </collision>
  </link>
  <joint name="FR_hip_joint" type="revolute">
    <origin xyz="0.1934 -0.0465 0" rpy="0 0 0" />
    <parent link="base" />
    <child link="FR_hip" />
    <axis xyz="1 0 0" />
    <limit lower="-1.0472" upper="1.0472" effort="23.7" velocity="30.1" />
  </joint>
  <link name="FR_hip_rotor">
    <inertial>
      <origin rpy="0 0 0" xyz="0.0 0.0 0.0" />
      <mass value="0.089" />
      <inertia ixx="0.000111842" ixy="0.0" ixz="0.0" iyy="0.000059647" iyz="0.0" izz="0.000059647" />
    </inertial>
  </link>
  <joint name="FR_hip_rotor_joint" type="fixed">
    <origin rpy="0 0 0" xyz="0.11215 -0.04675 0" />
    <parent link="base" />
    <child link="FR_hip_rotor" />
  </joint>
  <link name="FR_thigh">
    <inertial>
      <origin xyz="-0.00374 0.0223 -0.0327" rpy="0 0 0" />
      <mass value="1.152" />
      <inertia ixx="0.00584" ixy="-8.72E-05" ixz="-0.000289" iyy="0.0058" iyz="-0.000808" izz="0.00103" />
    </inertial>
    <visual>
      <origin xyz="0 0 0" rpy="0 0 0" />
      <geometry>
        <mesh filename="package://go_b/dae/thigh_mirror.dae" />
      </geometry>
      <material name="深色橡胶_012-effect"><color rgba="0.6717055 0.6924257 0.7742702 1" /></material><material name="Material_011-effect"><color rgba="0.9 0.95 0.95 1" /></material></visual>
    <collision>
      <origin rpy="0 1.5707963267948966 0" xyz="0 0 -0.1065" />
      <geometry>
        <box size="0.213 0.0245 0.034" />
      </geometry>
    </collision>
  </link>
  <joint name="FR_thigh_joint" type="revolute">
    <origin xyz="0 -0.0955 0" rpy="0 0 0" />
    <parent link="FR_hip" />
    <child link="FR_thigh" />
    <axis xyz="0 1 0" />
    <limit lower="-1.5708" upper="3.4907" effort="23.7" velocity="30.1" />
  </joint>
  <link name="FR_thigh_rotor">
    <inertial>
      <origin rpy="0 0 0" xyz="0.0 0.0 0.0" />
      <mass value="0.089" />
      <inertia ixx="0.000059647" ixy="0.0" ixz="0.0" iyy="0.000111842" iyz="0.0" izz="0.000059647" />
    </inertial>
  </link>
  <joint name="FR_thigh_rotor_joint" type="fixed">
    <origin rpy="0 0 0" xyz="0 0.00015 0" />
    <parent link="FR_hip" />
    <child link="FR_thigh_rotor" />
  </joint>
  <link name="FR_calf">
    <inertial>
      <origin xyz="0.00548 0.000975 -0.115" rpy="0 0 0" />
      <mass value="0.154" />
      <inertia ixx="0.00108" ixy="-3.4E-07" ixz="1.72E-05" iyy="0.0011" iyz="-8.28E-06" izz="3.29E-05" />
    </inertial>
    <visual>
      <origin xyz="0 0 0" rpy="0 0 0" />
      <geometry>
        <mesh filename="package://go_b/dae/calf_mirror.dae" />
      </geometry>
      <material name="黑色足端_006-effect"><color rgba="0 0 0 1" /></material><material name="深色橡胶_007-effect"><color rgba="0.6717055 0.6924257 0.7742702 1" /></material></visual>
    <collision>
      <origin rpy="0 -0.2 0" xyz="0.01 0 -0.06" />
      <geometry>
        <cylinder length="0.12" radius="0.013" />
      </geometry>
    </collision>
  </link>
  <joint name="FR_calf_joint" type="revolute">
    <origin xyz="0 0 -0.213" rpy="0 0 0" />
    <parent link="FR_thigh" />
    <child link="FR_calf" />
    <axis xyz="0 1 0" />
    <limit lower="-2.7227" upper="-0.83776" effort="45.43" velocity="15.70" />
  </joint>
  <link name="FR_calflower">
    <collision>
      <origin rpy="0 0 0" xyz="0 0 0" />
      <geometry>
        <cylinder length="0.065" radius="0.011" />
      </geometry>
    </collision>
  </link>
  <joint name="FR_calflower_joint" type="fixed">
    <origin xyz="0.020 0 -0.148" rpy="0 0.05 0" />
    <parent link="FR_calf" />
    <child link="FR_calflower" />
    <axis xyz="0 0 0" />
  </joint>
  <link name="FR_calflower1">
    <collision>
      <origin rpy="0 0 0" xyz="0 0 0" />
      <geometry>
        <cylinder length="0.03" radius="0.0155" />
      </geometry>
    </collision>
  </link>
  <joint name="FR_calflower1_joint" type="fixed">
    <origin xyz="-0.01 0 -0.04" rpy="0 0.48 0" />
    <parent link="FR_calflower" />
    <child link="FR_calflower1" />
    <axis xyz="0 0 0" />
  </joint>
  <link name="FR_calf_rotor">
    <inertial>
      <origin rpy="0 0 0" xyz="0.0 0.0 0.0" />
      <mass value="0.089" />
      <inertia ixx="0.000059647" ixy="0.0" ixz="0.0" iyy="0.000111842" iyz="0.0" izz="0.000059647" />
    </inertial>
  </link>
  <joint name="FR_calf_rotor_joint" type="fixed">
    <origin rpy="0 0 0" xyz="0 0.03235 0" />
    <parent link="FR_thigh" />
    <child link="FR_calf_rotor" />
  </joint>
  <link name="FR_foot">
    <inertial>
      <origin xyz="0 0 0" rpy="0 0 0" />
      <mass value="0.04" />
      <inertia ixx="9.6e-06" ixy="0" ixz="0" iyy="9.6e-06" iyz="0" izz="9.6e-06" />
    </inertial>
    <visual>
      <origin xyz="0 0 0" rpy="0 0 0" />
      <geometry>
        <mesh filename="package://go_b/dae/foot.dae" />
      </geometry>
      <material name="黑色足端_007-effect"><color rgba="0 0 0 1" /></material></visual>
    <collision>
      <origin rpy="0 0 0" xyz="-0.002 0 0" />
      <geometry>
        <sphere radius="0.022" />
      </geometry>
    </collision>
  </link>
  <joint name="FR_foot_joint" type="fixed" dont_collapse="true">
    <origin xyz="0 0 -0.213" rpy="0 0 0" />
    <parent link="FR_calf" />
    <child link="FR_foot" />
    <axis xyz="0 0 0" />
  </joint>
  <link name="RL_hip">
    <inertial>
      <origin xyz="0.0054 0.00194 -0.000105" rpy="0 0 0" />
      <mass value="0.678" />
      <inertia ixx="0.00048" ixy="3.01E-06" ixz="-1.11E-06" iyy="0.000884" iyz="-1.42E-06" izz="0.000596" />
    </inertial>
    <visual>
      <origin xyz="0 0 0" rpy="0 3.1415 0" />
      <geometry>
        <mesh filename="package://go_b/dae/hip.dae" />
      </geometry>
      <material name="深色橡胶_001-effect"><color rgba="0.6717055 0.6924257 0.7742702 1" /></material><material name="Material-effect"><color rgba="0.9 0.95 0.95 1" /></material></visual>
    <collision>
      <origin rpy="1.5707963267948966 0 0" xyz="0 0.08 0" />
      <geometry>
        <cylinder length="0.04" radius="0.046" />
      </geometry>
    </collision>
  </link>
  <joint name="RL_hip_joint" type="revolute">
    <origin xyz="-0.1934 0.0465 0" rpy="0 0 0" />
    <parent link="base" />
    <child link="RL_hip" />
    <axis xyz="1 0 0" />
    <limit lower="-1.0472" upper="1.0472" effort="23.7" velocity="30.1" />
  </joint>
  <link name="RL_hip_rotor">
    <inertial>
      <origin rpy="0 0 0" xyz="0.0 0.0 0.0" />
      <mass value="0.089" />
      <inertia ixx="0.000111842" ixy="0.0" ixz="0.0" iyy="0.000059647" iyz="0.0" izz="0.000059647" />
    </inertial>
  </link>
  <joint name="RL_hip_rotor_joint" type="fixed">
    <origin rpy="0 0 0" xyz="-0.11215 0.04675 0" />
    <parent link="base" />
    <child link="RL_hip_rotor" />
  </joint>
  <link name="RL_thigh">
    <inertial>
      <origin xyz="-0.00374 -0.0223 -0.0327" rpy="0 0 0" />
      <mass value="1.152" />
      <inertia ixx="0.00584" ixy="8.72E-05" ixz="-0.000289" iyy="0.0058" iyz="0.000808" izz="0.00103" />
    </inertial>
    <visual>
      <origin xyz="0 0 0" rpy="0 0 0" />
      <geometry>
        <mesh filename="package://go_b/dae/thigh.dae" />
      </geometry>
      <material name="深色橡胶_003-effect"><color rgba="0.6717055 0.6924257 0.7742702 1" /></material><material name="Material_009-effect"><color rgba="0.9 0.95 0.95 1" /></material></visual>
    <collision>
      <origin rpy="0 1.5707963267948966 0" xyz="0 0 -0.1065" />
      <geometry>
        <box size="0.213 0.0245 0.034" />
      </geometry>
    </collision>
  </link>
  <joint name="RL_thigh_joint" type="revolute">
    <origin xyz="0 0.0955 0" rpy="0 0 0" />
    <parent link="RL_hip" />
    <child link="RL_thigh" />
    <axis xyz="0 1 0" />
    <limit lower="-0.5236" upper="4.5379" effort="23.7" velocity="30.1" />
  </joint>
  <link name="RL_thigh_rotor">
    <inertial>
      <origin rpy="0 0 0" xyz="0.0 0.0 0.0" />
      <mass value="0.089" />
      <inertia ixx="0.000059647" ixy="0.0" ixz="0.0" iyy="0.000111842" iyz="0.0" izz="0.000059647" />
    </inertial>
  </link>
  <joint name="RL_thigh_rotor_joint" type="fixed">
    <origin rpy="0 0 0" xyz="0 -0.00015 0" />
    <parent link="RL_hip" />
    <child link="RL_thigh_rotor" />
  </joint>
  <link name="RL_calf">
    <inertial>
      <origin xyz="0.00548 -0.000975 -0.115" rpy="0 0 0" />
      <mass value="0.154" />
      <inertia ixx="0.00108" ixy="3.4E-07" ixz="1.72E-05" iyy="0.0011" iyz="8.28E-06" izz="3.29E-05" />
    </inertial>
    <visual>
      <origin xyz="0 0 0" rpy="0 0 0" />
      <geometry>
        <mesh filename="package://go_b/dae/calf.dae" />
      </geometry>
      <material name="黑色足端_005-effect"><color rgba="0 0 0 1" /></material><material name="深色橡胶_005-effect"><color rgba="0.6717055 0.6924257 0.7742702 1" /></material></visual>
    <collision>
      <origin rpy="0 -0.2 0" xyz="0.01 0 -0.06" />
      <geometry>
        <cylinder length="0.12" radius="0.013" />
      </geometry>
    </collision>
  </link>
  <joint name="RL_calf_joint" type="revolute">
    <origin xyz="0 0 -0.213" rpy="0 0 0" />
    <parent link="RL_thigh" />
    <child link="RL_calf" />
    <axis xyz="0 1 0" />
    <limit lower="-2.7227" upper="-0.83776" effort="45.43" velocity="15.70" />
  </joint>
  <link name="RL_calflower">
    <collision>
      <origin rpy="0 0 0" xyz="0 0 0" />
      <geometry>
        <cylinder length="0.065" radius="0.011" />
      </geometry>
    </collision>
  </link>
  <joint name="RL_calflower_joint" type="fixed">
    <origin xyz="0.020 0 -0.148" rpy="0 0.05 0" />
    <parent link="RL_calf" />
    <child link="RL_calflower" />
    <axis xyz="0 0 0" />
  </joint>
  <link name="RL_calflower1">
    <collision>
      <origin rpy="0 0 0" xyz="0 0 0" />
      <geometry>
        <cylinder length="0.03" radius="0.0155" />
      </geometry>
    </collision>
  </link>
  <joint name="RL_calflower1_joint" type="fixed">
    <origin xyz="-0.01 0 -0.04" rpy="0 0.48 0" />
    <parent link="RL_calflower" />
    <child link="RL_calflower1" />
    <axis xyz="0 0 0" />
  </joint>
  <link name="RL_calf_rotor">
    <inertial>
      <origin rpy="0 0 0" xyz="0.0 0.0 0.0" />
      <mass value="0.089" />
      <inertia ixx="0.000059647" ixy="0.0" ixz="0.0" iyy="0.000111842" iyz="0.0" izz="0.000059647" />
    </inertial>
  </link>
  <joint name="RL_calf_rotor_joint" type="fixed">
    <origin rpy="0 0 0" xyz="0 -0.03235 0" />
    <parent link="RL_thigh" />
    <child link="RL_calf_rotor" />
  </joint>
  <link name="RL_foot">
    <inertial>
      <origin xyz="0 0 0" rpy="0 0 0" />
      <mass value="0.04" />
      <inertia ixx="9.6e-06" ixy="0" ixz="0" iyy="9.6e-06" iyz="0" izz="9.6e-06" />
    </inertial>
    <visual>
      <origin xyz="0 0 0" rpy="0 0 0" />
      <geometry>
        <mesh filename="package://go_b/dae/foot.dae" />
      </geometry>
      <material name="黑色足端_007-effect"><color rgba="0 0 0 1" /></material></visual>
    <collision>
      <origin rpy="0 0 0" xyz="-0.002 0 0" />
      <geometry>
        <sphere radius="0.022" />
      </geometry>
    </collision>
  </link>
  <joint name="RL_foot_joint" type="fixed" dont_collapse="true">
    <origin xyz="0 0 -0.213" rpy="0 0 0" />
    <parent link="RL_calf" />
    <child link="RL_foot" />
    <axis xyz="0 0 0" />
  </joint>
  <link name="RR_hip">
    <inertial>
      <origin xyz="0.0054 -0.00194 -0.000105" rpy="0 0 0" />
      <mass value="0.678" />
      <inertia ixx="0.00048" ixy="-3.01E-06" ixz="-1.11E-06" iyy="0.000884" iyz="1.42E-06" izz="0.000596" />
    </inertial>
    <visual>
      <origin xyz="0 0 0" rpy="3.1415 3.1415 0" />
      <geometry>
        <mesh filename="package://go_b/dae/hip.dae" />
      </geometry>
      <material name="深色橡胶_001-effect"><color rgba="0.6717055 0.6924257 0.7742702 1" /></material><material name="Material-effect"><color rgba="0.9 0.95 0.95 1" /></material></visual>
    <collision>
      <origin rpy="1.5707963267948966 0 0" xyz="0 -0.08 0" />
      <geometry>
        <cylinder length="0.04" radius="0.046" />
      </geometry>
    </collision>
  </link>
  <joint name="RR_hip_joint" type="revolute">
    <origin xyz="-0.1934 -0.0465 0" rpy="0 0 0" />
    <parent link="base" />
    <child link="RR_hip" />
    <axis xyz="1 0 0" />
    <limit lower="-1.0472" upper="1.0472" effort="23.7" velocity="30.1" />
  </joint>
  <link name="RR_hip_rotor">
    <inertial>
      <origin rpy="0 0 0" xyz="0.0 0.0 0.0" />
      <mass value="0.089" />
      <inertia ixx="0.000111842" ixy="0.0" ixz="0.0" iyy="0.000059647" iyz="0.0" izz="0.000059647" />
    </inertial>
  </link>
  <joint name="RR_hip_rotor_joint" type="fixed">
    <origin rpy="0 0 0" xyz="-0.11215 -0.04675 0" />
    <parent link="base" />
    <child link="RR_hip_rotor" />
  </joint>
  <link name="RR_thigh">
    <inertial>
      <origin xyz="-0.00374 0.0223 -0.0327" rpy="0 0 0" />
      <mass value="1.152" />
      <inertia ixx="0.00584" ixy="-8.72E-05" ixz="-0.000289" iyy="0.0058" iyz="-0.000808" izz="0.00103" />
    </inertial>
    <visual>
      <origin xyz="0 0 0" rpy="0 0 0" />
      <geometry>
        <mesh filename="package://go_b/dae/thigh_mirror.dae" />
      </geometry>
      <material name="深色橡胶_012-effect"><color rgba="0.6717055 0.6924257 0.7742702 1" /></material><material name="Material_011-effect"><color rgba="0.9 0.95 0.95 1" /></material></visual>
    <collision>
      <origin rpy="0 1.5707963267948966 0" xyz="0 0 -0.1065" />
      <geometry>
        <box size="0.213 0.0245 0.034" />
      </geometry>
    </collision>
  </link>
  <joint name="RR_thigh_joint" type="revolute">
    <origin xyz="0 -0.0955 0" rpy="0 0 0" />
    <parent link="RR_hip" />
    <child link="RR_thigh" />
    <axis xyz="0 1 0" />
    <limit lower="-0.5236" upper="4.5379" effort="23.7" velocity="30.1" />
  </joint>
  <link name="RR_thigh_rotor">
    <inertial>
      <origin rpy="0 0 0" xyz="0.0 0.0 0.0" />
      <mass value="0.089" />
      <inertia ixx="0.000059647" ixy="0.0" ixz="0.0" iyy="0.000111842" iyz="0.0" izz="0.000059647" />
    </inertial>
  </link>
  <joint name="RR_thigh_rotor_joint" type="fixed">
    <origin rpy="0 0 0" xyz="0 0.00015 0" />
    <parent link="RR_hip" />
    <child link="RR_thigh_rotor" />
  </joint>
  <link name="RR_calf">
    <inertial>
      <origin xyz="0.00548 0.000975 -0.115" rpy="0 0 0" />
      <mass value="0.154" />
      <inertia ixx="0.00108" ixy="-3.4E-07" ixz="1.72E-05" iyy="0.0011" iyz="-8.28E-06" izz="3.29E-05" />
    </inertial>
    <visual>
      <origin xyz="0 0 0" rpy="0 0 0" />
      <geometry>
        <mesh filename="package://go_b/dae/calf_mirror.dae" />
      </geometry>
      <material name="黑色足端_006-effect"><color rgba="0 0 0 1" /></material><material name="深色橡胶_007-effect"><color rgba="0.6717055 0.6924257 0.7742702 1" /></material></visual>
    <collision>
      <origin rpy="0 -0.2 0" xyz="0.01 0 -0.06" />
      <geometry>
        <cylinder length="0.12" radius="0.013" />
      </geometry>
    </collision>
  </link>
  <joint name="RR_calf_joint" type="revolute">
    <origin xyz="0 0 -0.213" rpy="0 0 0" />
    <parent link="RR_thigh" />
    <child link="RR_calf" />
    <axis xyz="0 1 0" />
    <limit lower="-2.7227" upper="-0.83776" effort="45.43" velocity="15.70" />
  </joint>
  <link name="RR_calflower">
    <collision>
      <origin rpy="0 0 0" xyz="0 0 0" />
      <geometry>
        <cylinder length="0.065" radius="0.011" />
      </geometry>
    </collision>
  </link>
  <joint name="RR_calflower_joint" type="fixed">
    <origin xyz="0.020 0 -0.148" rpy="0 0.05 0" />
    <parent link="RR_calf" />
    <child link="RR_calflower" />
    <axis xyz="0 0 0" />
  </joint>
  <link name="RR_calflower1">
    <collision>
      <origin rpy="0 0 0" xyz="0 0 0" />
      <geometry>
        <cylinder length="0.03" radius="0.0155" />
      </geometry>
    </collision>
  </link>
  <joint name="RR_calflower1_joint" type="fixed">
    <origin xyz="-0.01 0 -0.04" rpy="0 0.48 0" />
    <parent link="RR_calflower" />
    <child link="RR_calflower1" />
    <axis xyz="0 0 0" />
  </joint>
  <link name="RR_calf_rotor">
    <inertial>
      <origin rpy="0 0 0" xyz="0.0 0.0 0.0" />
      <mass value="0.089" />
      <inertia ixx="0.000059647" ixy="0.0" ixz="0.0" iyy="0.000111842" iyz="0.0" izz="0.000059647" />
    </inertial>
  </link>
  <joint name="RR_calf_rotor_joint" type="fixed">
    <origin rpy="0 0 0" xyz="0 0.03235 0" />
    <parent link="RR_thigh" />
    <child link="RR_calf_rotor" />
  </joint>
  <link name="RR_foot">
    <inertial>
      <origin xyz="0 0 0" rpy="0 0 0" />
      <mass value="0.04" />
      <inertia ixx="9.6e-06" ixy="0" ixz="0" iyy="9.6e-06" iyz="0" izz="9.6e-06" />
    </inertial>
    <visual>
      <origin xyz="0 0 0" rpy="0 0 0" />
      <geometry>
        <mesh filename="package://go_b/dae/foot.dae" />
      </geometry>
      <material name="黑色足端_007-effect"><color rgba="0 0 0 1" /></material></visual>
    <collision>
      <origin rpy="0 0 0" xyz="-0.002 0 0" />
      <geometry>
        <sphere radius="0.022" />
      </geometry>
    </collision>
  </link>
  <joint name="RR_foot_joint" type="fixed" dont_collapse="true">
    <origin xyz="0 0 -0.213" rpy="0 0 0" />
    <parent link="RR_calf" />
    <child link="RR_foot" />
    <axis xyz="0 0 0" />
  </joint>
  <link name="imu">
    <inertial>
      <origin xyz="0 0 0" rpy="0 0 0" />
      <mass value="0" />
      <inertia ixx="0" ixy="0" ixz="0" iyy="0" iyz="0" izz="0" />
    </inertial>
  </link>
  <joint name="imu_joint" type="fixed">
    <origin xyz="-0.02557 0 0.04232" rpy="0 0 0" />
    <parent link="base" />
    <child link="imu" />
    <axis xyz="0 0 0" />
  </joint>
  <link name="radar">
    <inertial>
      <origin xyz="0 0 0" rpy="0 0 0" />
      <mass value="0" />
      <inertia ixx="0" ixy="0" ixz="0" iyy="0" iyz="0" izz="0" />
    </inertial>
  </link>
  <joint name="radar_joint" type="fixed">
    <origin xyz="0.28945 0 -0.046825" rpy="0 2.8782 0" />
    <parent link="base" />
    <child link="radar" />
    <axis xyz="0 0 0" />
  </joint>
  <joint name="front_camera_joint" type="fixed">
    <origin rpy="0 0 0" xyz="0.32715 -0.00003 0.04297" />
      <parent link="base" />
      <child link="front_camera" />
  </joint>
  <link name="front_camera">
  </link>
<!-- Arm Links -->
  <link name="arm_base_link">
        <inertial>
            <origin xyz="-0.00473641164191482 2.56829134630247E-05 0.041451518036016" rpy="0 0 0"/>
            <mass value="1.02" />
            <inertia ixx="0.00267433" ixy="-0.00000073" ixz="-0.00017389" iyy="0.00282612" iyz="0.0000004" izz="0.00089624"/>
        </inertial>
        <visual>
            <origin xyz="0 0 0" rpy="0 0 0"/>
            <geometry>
                <mesh filename="package://go_b/meshes/piper/dae/base_link.dae"/>
            </geometry>
        </visual>
        <collision>
            <origin xyz="0 0 0" rpy="0 0 0"/>
            <geometry>
                <mesh filename="package://go_b/meshes/piper/base_link.stl"/>
            </geometry>
        </collision>
    </link>
    <joint name="arm_base_joint" type="fixed">
        <origin xyz="0.15 0 0.085" rpy="0 0 0"/>
        <parent link="base"/>
        <child link="arm_base_link"/>
        <axis xyz="0 0 1"/>
        <limit lower="-2.6179938" upper="2.6179938" effort="100" velocity="5"/>
    </joint>
    <link name="arm_link1">
        <inertial>
            <origin xyz="0.00032 -0.00041 -0.00348" rpy="0 0 0"/>
            <mass value="0.71"/>
            <inertia ixx="0.00050027" ixy="0.00000078" ixz="0.00000626" iyy="0.00040879" iyz="0.00000462" izz="0.00045802"/>
        </inertial>
        <visual>
            <origin xyz="0 0 0" rpy="0 0 0"/>
            <geometry>
                <mesh filename="package://go_b/meshes/piper/dae/link1.dae"/>
            </geometry>
        </visual>
        <collision>
            <origin xyz="0 0 0" rpy="0 0 0"/>
            <geometry>
                <mesh filename="package://go_b/meshes/piper/link1.stl"/>
            </geometry>
        </collision>
    </link>
    <joint name="arm_joint1" type="revolute">
        <origin xyz="0 0 0.123" rpy="0 0 0"/>
        <parent link="arm_base_link"/>
        <child link="arm_link1"/>
        <axis xyz="0 0 1"/>
        <limit lower="-2.6179938" upper="2.6179938" effort="100" velocity="5"/>
    </joint>
    <link name="arm_link2">
        <inertial>
            <origin xyz="0.21852 -0.00861 0.00126" rpy="0 0 0"/>
            <mass value="1.16"/>
            <inertia ixx="0.00111915" ixy="0.00182916" ixz="0.00019233" iyy="0.06763251" iyz="0.00000767" izz="0.067559"/>
        </inertial>
        <visual>
            <origin xyz="0 0 0" rpy="0 0 0"/>
            <geometry>
                <mesh filename="package://go_b/meshes/piper/dae/link2.dae"/>
            </geometry>
        </visual>
        <collision>
            <origin xyz="0 0 0" rpy="0 0 0"/>
            <geometry>
                <mesh filename="package://go_b/meshes/piper/link2.stl"/>
            </geometry>
        </collision>
    </link>
    <joint name="arm_joint2" type="revolute">
        <origin xyz="0 0 0" rpy="1.5707963 -0.1357866 -3.1415926"/>
        <parent link="arm_link1"/>
        <child link="arm_link2"/>
        <axis xyz="0 0 1"/>
        <limit lower="0" upper="3.1415926" effort="100" velocity="5"/>
    </joint>
    <link name="arm_link3">
        <inertial>
            <origin xyz="-0.01999 -0.14808 -0.00053" rpy="0 0 0"/>
            <mass value="0.5"/>
            <inertia ixx="0.01347608" ixy="0.00161034" ixz="0.00000066" iyy="0.00046377" iyz="0.00000162" izz="0.01363321"/>
        </inertial>
        <visual>
            <origin xyz="0 0 0" rpy="0 0 0"/>
            <geometry>
                <mesh filename="package://go_b/meshes/piper/dae/link3.dae"/>
            </geometry>
        </visual>
        <collision>
            <origin xyz="0 0 0" rpy="0 0 0"/>
            <geometry>
                <mesh filename="package://go_b/meshes/piper/link3.stl"/>
            </geometry>
        </collision>
    </link>
    <joint name="arm_joint3" type="revolute">
        <origin xyz="0.28503 0 0" rpy="0 0 -1.7938494"/>
        <parent link="arm_link2"/>
        <child link="arm_link3"/>
        <axis xyz="0 0 1"/>
        <limit lower="-2.9670597" upper="0" effort="100" velocity="5"/>
    </joint>
    <link name="arm_link4">
        <inertial>
            <origin xyz="0.00013 -0.00076 -0.00394" rpy="0 0 0"/>
            <mass value="0.38"/>
            <inertia ixx="0.00017844" ixy="0.00000062" ixz="0.00000067" iyy="0.00018914" iyz="0.00000408" izz="0.00014613"/>
        </inertial>
        <visual>
            <origin xyz="0 0 0" rpy="0 0 0"/>
            <geometry>
                <mesh filename="package://go_b/meshes/piper/dae/link4.dae"/>
            </geometry>
        </visual>
        <collision>
            <origin xyz="0 0 0" rpy="0 0 0"/>
            <geometry>
                <mesh filename="package://go_b/meshes/piper/link4.stl"/>
            </geometry>
        </collision>
    </link>
    <joint name="arm_joint4" type="revolute">
        <origin xyz="-0.02198 -0.25075 0" rpy="1.5707963 0 0"/>
        <parent link="arm_link3"/>
        <child link="arm_link4"/>
        <axis xyz="0 0 1"/>
        <limit lower="-1.7453292" upper="1.7453292" effort="100" velocity="5"/>
    </joint>
    <link name="arm_link5">
        <inertial>
            <origin xyz="0.00018 -0.06104 -0.00227" rpy="0 0 0"/>
            <mass value="0.383"/>
            <inertia ixx="0.00172318" ixy="0.00000259" ixz="0.00000010" iyy="0.00017936" iyz="0.00000990" izz="0.00171172"/>
        </inertial>
        <visual>
            <origin xyz="0 0 0" rpy="0 0 0"/>
            <geometry>
                <mesh filename="package://go_b/meshes/piper/dae/link5.dae"/>
            </geometry>
        </visual>
        <collision>
            <origin xyz="0 0 0" rpy="0 0 0"/>
            <geometry>
                <mesh filename="package://go_b/meshes/piper/link5.stl"/>
            </geometry>
        </collision>
    </link>
    <joint name="arm_joint5" type="revolute">
        <origin xyz="0 0 0" rpy="-1.5707963 0 0"/>
        <parent link="arm_link4"/>
        <child link="arm_link5"/>
        <axis xyz="0 0 1"/>
        <limit lower="-1.2217304" upper="1.2217304" effort="100" velocity="5"/>
    </joint>
    <link name="arm_link6">
        <inertial>
            <origin xyz="-0.00003 0.00006 -0.002" rpy="0 0 0"/>
            <mass value="0.007"/>
            <inertia ixx="0.00152112" ixy="0.00000202" ixz="0.00000261" iyy="0.00138626" iyz="0.00000002" izz="0.00031152"/>
        </inertial>
        <visual>
            <origin xyz="0 0 0" rpy="0 0 0"/>
            <geometry>
                <mesh filename="package://go_b/meshes/piper/dae/link6.dae"/>
            </geometry>
        </visual>
        <collision>
            <origin xyz="0 0 0" rpy="0 0 0"/>
            <geometry>
                <mesh filename="package://go_b/meshes/piper/link6.stl"/>
            </geometry>
        </collision>
    </link>
    <joint name="arm_joint6" type="revolute">
        <origin xyz="8.8259E-05 -0.091 0" rpy="1.5707963 0 0"/>
        <parent link="arm_link5"/>
        <child link="arm_link6"/>
        <axis xyz="0 0 1"/>
        <limit lower="-2.0943951" upper="2.0943951" effort="100" velocity="5"/>
    </joint>
        <link name="gripper_base">
        <inertial>
            <origin xyz="-0.000183807162235591 8.05033155577911E-05 0.0321436689908876" rpy="0 0 0"/>
            <mass value="0.45"/>
            <inertia ixx="0.00092934" ixy="0.00000034" ixz="-0.00000738" iyy="0.00071447" iyz="0.00000005" izz="0.00039442"/>
        </inertial>
        <visual>
            <origin xyz="0 0 0" rpy="0 0 0"/>
            <geometry>
                <mesh filename="package://go_b/meshes/piper/dae/gripper_base.dae"/>
            </geometry>
        </visual>
        <collision>
            <origin xyz="0 0 0" rpy="0 0 0"/>
            <geometry>
                <mesh filename="package://go_b/meshes/piper/gripper_base.stl"/>
            </geometry>
        </collision>
    </link>
    <joint name="gripper_base_joint" type="fixed">
        <origin xyz="0 0 0" rpy="0 0 0"/>
        <parent link="arm_link6"/>
        <child link="gripper_base"/>
    </joint>
    <link name="gripper_link1">
        <inertial>
            <origin xyz="0.00065123185041968 -0.0491929869131989 0.00972258769184025" rpy="0 0 0"/>
            <mass value="0.025"/>
            <inertia ixx="0.00007371" ixy="-0.00000113" ixz="0.00000021" iyy="0.00000781" iyz="-0.00001372" izz="0.0000747"/>
        </inertial>
        <visual>
            <origin xyz="0 0 0" rpy="0 0 0"/>
            <geometry>
                <mesh filename="package://go_b/meshes/piper/dae/gripper_link1.dae"/>
            </geometry>
        </visual>
        <collision>
            <origin xyz="0 0 0" rpy="0 0 0"/>
            <geometry>
                <mesh filename="package://go_b/meshes/piper/gripper_link1.stl"/>
            </geometry>
        </collision>
    </link>
    <joint name="gripper_joint1" type="prismatic">
        <origin xyz="0 0 0.1358" rpy="1.5707963 0 0"/>
        <parent link="gripper_base"/>
        <child link="gripper_link1"/>
        <axis xyz="0 0 1"/>
        <limit lower="0" upper="0.05" effort="10" velocity="3"/>
    </joint>
    <link name="gripper_link2">
        <inertial>
            <origin xyz="0.00065123185041968 -0.0491929869131989 0.00972258769184025" rpy="0 0 0"/>
            <mass value="0.025"/>
            <inertia ixx="0.00007371" ixy="-0.00000113" ixz="0.00000021" iyy="0.00000781" iyz="-0.00001372" izz="0.0000747"/>
        </inertial>
        <visual>
            <origin xyz="0 0 0" rpy="0 0 0"/>
            <geometry>
                <mesh filename="package://go_b/meshes/piper/dae/gripper_link2.dae"/>
            </geometry>
        </visual>
        <collision>
            <origin xyz="0 0 0" rpy="0 0 0"/>
            <geometry>
                <mesh filename="package://go_b/meshes/piper/gripper_link2.stl"/>
            </geometry>
        </collision>
    </link>
    <joint name="gripper_joint2" type="prismatic">
        <origin xyz="0 0 0.1358" rpy="1.5707963 0 -3.1415926"/>
        <parent link="gripper_base"/>
        <child link="gripper_link2"/>
        <axis xyz="0 0 -1"/>
        <limit lower="-0.05" upper="0" effort="10" velocity="3"/>
    </joint>
</robot>